# Processing Error for CVE-2022-2141

# Error Processing CVE-2022-2141

Time: 2025-03-31T12:05:17.859684

## Error Message

Error processing CVE-2022-2141: 500 Unable to submit request because the service is temporarily unavailable.

## Traceback

```
Traceback (most recent call last):
  File "/home/chris/work/CyberSecAI/top25_cwe_assign_compare/assign_cwe/src/utils/vulnerability_processor.py", line 531, in batch_process_retrievals
    analysis, cwe_ids, relationship_analysis = self.process_analyzer_agent(
                                               ^^^^^^^^^^^^^^^^^^^^^^^^^^^^
  File "/home/chris/work/CyberSecAI/top25_cwe_assign_compare/assign_cwe/src/utils/vulnerability_processor.py", line 739, in process_analyzer_agent
    analyzer_response = self.kb.agents["analyzer"].generate_response(enhanced_query)
                        ^^^^^^^^^^^^^^^^^^^^^^^^^^^^^^^^^^^^^^^^^^^^^^^^^^^^^^^^^^^^
  File "/home/chris/work/CyberSecAI/top25_cwe_assign_compare/assign_cwe/src/agents/enhanced_llm_with_relationships.py", line 135, in generate_response
    basic_response = super().generate_response(input_text)
                     ^^^^^^^^^^^^^^^^^^^^^^^^^^^^^^^^^^^^^
  File "/home/chris/work/CyberSecAI/top25_cwe_assign_compare/assign_cwe/src/agents/enhanced_llm.py", line 559, in generate_response
    llm_response = self._call_llm(prompt)
                   ^^^^^^^^^^^^^^^^^^^^^^
  File "/home/chris/work/CyberSecAI/top25_cwe_assign_compare/assign_cwe/src/agents/enhanced_llm_with_relationships.py", line 99, in _call_llm
    response = self.llm.invoke(messages)
               ^^^^^^^^^^^^^^^^^^^^^^^^^
  File "/home/chris/work/CyberSecAI/top25_cwe_assign_compare/env/lib/python3.12/site-packages/langchain_core/language_models/chat_models.py", line 284, in invoke
    self.generate_prompt(
  File "/home/chris/work/CyberSecAI/top25_cwe_assign_compare/env/lib/python3.12/site-packages/langchain_core/language_models/chat_models.py", line 860, in generate_prompt
    return self.generate(prompt_messages, stop=stop, callbacks=callbacks, **kwargs)
           ^^^^^^^^^^^^^^^^^^^^^^^^^^^^^^^^^^^^^^^^^^^^^^^^^^^^^^^^^^^^^^^^^^^^^^^^
  File "/home/chris/work/CyberSecAI/top25_cwe_assign_compare/env/lib/python3.12/site-packages/langchain_core/language_models/chat_models.py", line 690, in generate
    self._generate_with_cache(
  File "/home/chris/work/CyberSecAI/top25_cwe_assign_compare/env/lib/python3.12/site-packages/langchain_core/language_models/chat_models.py", line 925, in _generate_with_cache
    result = self._generate(
             ^^^^^^^^^^^^^^^
  File "/home/chris/work/CyberSecAI/top25_cwe_assign_compare/env/lib/python3.12/site-packages/langchain_google_genai/chat_models.py", line 961, in _generate
    response: GenerateContentResponse = _chat_with_retry(
                                        ^^^^^^^^^^^^^^^^^
  File "/home/chris/work/CyberSecAI/top25_cwe_assign_compare/env/lib/python3.12/site-packages/langchain_google_genai/chat_models.py", line 201, in _chat_with_retry
    return _chat_with_retry(**kwargs)
           ^^^^^^^^^^^^^^^^^^^^^^^^^^
  File "/home/chris/work/CyberSecAI/top25_cwe_assign_compare/env/lib/python3.12/site-packages/tenacity/__init__.py", line 336, in wrapped_f
    return copy(f, *args, **kw)
           ^^^^^^^^^^^^^^^^^^^^
  File "/home/chris/work/CyberSecAI/top25_cwe_assign_compare/env/lib/python3.12/site-packages/tenacity/__init__.py", line 475, in __call__
    do = self.iter(retry_state=retry_state)
         ^^^^^^^^^^^^^^^^^^^^^^^^^^^^^^^^^^
  File "/home/chris/work/CyberSecAI/top25_cwe_assign_compare/env/lib/python3.12/site-packages/tenacity/__init__.py", line 376, in iter
    result = action(retry_state)
             ^^^^^^^^^^^^^^^^^^^
  File "/home/chris/work/CyberSecAI/top25_cwe_assign_compare/env/lib/python3.12/site-packages/tenacity/__init__.py", line 418, in exc_check
    raise retry_exc.reraise()
          ^^^^^^^^^^^^^^^^^^^
  File "/home/chris/work/CyberSecAI/top25_cwe_assign_compare/env/lib/python3.12/site-packages/tenacity/__init__.py", line 185, in reraise
    raise self.last_attempt.result()
          ^^^^^^^^^^^^^^^^^^^^^^^^^^
  File "/usr/lib/python3.12/concurrent/futures/_base.py", line 449, in result
    return self.__get_result()
           ^^^^^^^^^^^^^^^^^^^
  File "/usr/lib/python3.12/concurrent/futures/_base.py", line 401, in __get_result
    raise self._exception
  File "/home/chris/work/CyberSecAI/top25_cwe_assign_compare/env/lib/python3.12/site-packages/tenacity/__init__.py", line 478, in __call__
    result = fn(*args, **kwargs)
             ^^^^^^^^^^^^^^^^^^^
  File "/home/chris/work/CyberSecAI/top25_cwe_assign_compare/env/lib/python3.12/site-packages/langchain_google_genai/chat_models.py", line 199, in _chat_with_retry
    raise e
  File "/home/chris/work/CyberSecAI/top25_cwe_assign_compare/env/lib/python3.12/site-packages/langchain_google_genai/chat_models.py", line 183, in _chat_with_retry
    return generation_method(**kwargs)
           ^^^^^^^^^^^^^^^^^^^^^^^^^^^
  File "/home/chris/work/CyberSecAI/top25_cwe_assign_compare/env/lib/python3.12/site-packages/google/ai/generativelanguage_v1beta/services/generative_service/client.py", line 864, in generate_content
    response = rpc(
               ^^^^
  File "/home/chris/work/CyberSecAI/top25_cwe_assign_compare/env/lib/python3.12/site-packages/google/api_core/gapic_v1/method.py", line 131, in __call__
    return wrapped_func(*args, **kwargs)
           ^^^^^^^^^^^^^^^^^^^^^^^^^^^^^
  File "/home/chris/work/CyberSecAI/top25_cwe_assign_compare/env/lib/python3.12/site-packages/google/api_core/retry/retry_unary.py", line 293, in retry_wrapped_func
    return retry_target(
           ^^^^^^^^^^^^^
  File "/home/chris/work/CyberSecAI/top25_cwe_assign_compare/env/lib/python3.12/site-packages/google/api_core/retry/retry_unary.py", line 153, in retry_target
    _retry_error_helper(
  File "/home/chris/work/CyberSecAI/top25_cwe_assign_compare/env/lib/python3.12/site-packages/google/api_core/retry/retry_base.py", line 212, in _retry_error_helper
    raise final_exc from source_exc
  File "/home/chris/work/CyberSecAI/top25_cwe_assign_compare/env/lib/python3.12/site-packages/google/api_core/retry/retry_unary.py", line 144, in retry_target
    result = target()
             ^^^^^^^^
  File "/home/chris/work/CyberSecAI/top25_cwe_assign_compare/env/lib/python3.12/site-packages/google/api_core/timeout.py", line 130, in func_with_timeout
    return func(*args, **kwargs)
           ^^^^^^^^^^^^^^^^^^^^^
  File "/home/chris/work/CyberSecAI/top25_cwe_assign_compare/env/lib/python3.12/site-packages/google/api_core/grpc_helpers.py", line 78, in error_remapped_callable
    raise exceptions.from_grpc_error(exc) from exc
google.api_core.exceptions.InternalServerError: 500 Unable to submit request because the service is temporarily unavailable.

```